<?xml version="1.0"?>
<robot xmlns:xacro="http://ros.org/wiki/xacro">
  <xacro:macro name="akariservo" params="parent *joint_servo">
    <joint name="servo_joint" type="continuous">
      <xacro:insert_block name="joint_servo" />
      <axis xyz="0.0 0.0 1.0" />
      <parent link="${parent}" />
      <child link="servo_link" />
      <limit effort="5.0" velocity="1.5" lower="-2.0" upper="2.0" />
      <dynamics damping="1.0"/>
    </joint>

    <link name="servo_link">
      <visual>
        <geometry>
          <mesh filename="$(find state_publisher)/akari_gazebo_model/akari_servo.stl" />
        </geometry>
      </visual>

      <collision>
        <geometry>
          <mesh filename="$(find state_publisher)/akari_gazebo_model/akari_servo.stl" />
        </geometry>
      </collision>

      <inertial>
        <origin xyz="0.0 0 0.0" />
        <mass value="0.50" />
        <inertia ixx="0.0025" ixy="0.0" iyy="0.0025" ixz="0.0" iyz="0.0" izz="0.0025" />
      </inertial>
    </link>
  </xacro:macro>
</robot>


