<?xml version="1.0"?>
<robot xmlns:xacro="http://ros.org/wiki/xacro">
  <xacro:macro name="akarihead" params="parent *joint_head">
    <joint name="tilt" type="continuous">
      <xacro:insert_block name="joint_head" />
      <axis xyz="1.0 0.0 0.0" />
      <parent link="${parent}" />
      <child link="head_link" />
      <limit effort="5.0" velocity="1.5" lower="-0.5" upper="0.8" />
      <dynamics damping="1.0"/>
    </joint>
    
    <link name="head_link">
      <visual>
        <geometry>
          <mesh filename="$(find state_publisher)/akari_gazebo_model/akari_head.stl" />
        </geometry>
      </visual>
      
      <collision>
        <geometry>
          <mesh filename="$(find state_publisher)/akari_gazebo_model/akari_head.stl" />
        </geometry>
      </collision>
      
      <inertial>
        <origin xyz="0.0 0.0 0.0" />
        <mass value="0.500"/>
        <inertia ixx="0.0013541667" ixy="0" ixz="0" iyy="0.0013541667" iyz="0" izz="0.0025"/>
      </inertial>
    </link>
  </xacro:macro>
</robot>
